<?xml version="1.0"?>
<robot xmlns:xacro="http://www.ros.org/wiki/xacro" name="sagan">
 <!--  <pose>0 0 0.4 0 0 0</pose>
 <link name="base_link">
    <origin
      xyz="0 0 0"
      rpy="0 0 0" />
  </link >
  <joint name="base_link_to_sagan_link=" type="fixed">
    <parent link="base_link"/>
    <child link="sagan_link"/>
    <origin
      xyz="0 0 0.150"
      rpy="0 0 0" />
  </joint>-->
  <link  name="sagan_link">
    <origin
        xyz="0.0249786097496162 0.00158090414679702 0.384335554461826"
        rpy="0 0 0.384335554461826" />
    <inertial>
      <origin
        xyz="0.0249786097496162 0.00158090414679702 0.384335554461826"
        rpy="0 0 0.384335554461826" />
      <mass
        value="0.27066592924889" />
      <inertia
        ixx="0.6022"
        ixy="-0.02364"
        ixz="-0.1197"
        iyy="1.7386"
        iyz="-0.001544"
        izz="2.0296" />
    </inertial>
    <visual>
      <origin
        xyz="0 0 0"
        rpy="0 0 0" />
      <geometry>
        <mesh
          filename="model://meshes/base_link.STL" />
      </geometry>
      <material
        name="">
        <color
          rgba="0.898039215686275 0.917647058823529 0.929411764705882 1" />
      </material>
    </visual>
    <collision>
      <origin
        xyz="0 0 0.384335554461826"
        rpy="0 0 0.384335554461826" />
      <geometry>
        <mesh
          filename="model://meshes/base_link.STL" />
      </geometry>
    </collision>
  </link>
  <link  name="Susp_right">
    <inertial>
      <origin
        xyz="1.91516963860688E-07 -0.050740645517996 -0.0172301314016279"
        rpy="0 0 0" />
      <mass
        value="0.561111370318225" />
      <inertia
        ixx="0.00129127869130011"
        ixy="0"
        ixz="0"
        iyy="0.00662831035722674"
        iyz="-0.000306651386400898"
        izz="0.00760703794507664" />
    </inertial>
    <visual>
      <origin
        xyz="0 0 0"
        rpy="0 0 0" />
      <geometry>
        <mesh
          filename="model://meshes/Susp_right.STL" />
      </geometry>
      <material
        name="">
        <color
          rgba="0.898039215686275 0.917647058823529 0.929411764705882 1" />
      </material>
    </visual>
    <collision>
      <origin
        xyz="0 0 0"
        rpy="0 0 0" />
      <geometry>
        <mesh
          filename="model://meshes/Susp_right.STL" />
      </geometry>
    </collision>
  </link>
  <joint name="Susp_right_join"
    type="fixed">
    <origin
      xyz="0 -0.130 0"
      rpy="-1.57 0 0" />
    <parent
      link="sagan_link" />
    <child
      link="Susp_right" />
    <axis
      xyz="0 0 1" />
  </joint>
  <link  name="FR_wheel">
    <inertial>
      <mass
        value="0.156306129053996" />
      <inertia
        ixx="0.01"
        ixy="0.000"
        ixz="0"
        iyy="0.01"
        iyz="0"
        izz="0.01" />
    </inertial>
    <visual>
      <geometry>
        <mesh
          filename="model://meshes/FR_wheel.STL" />
      </geometry>
      <material
        name="">
        <color
          rgba="0.796078431372549 0.823529411764706 0.937254901960784 1" />
      </material>
    </visual>
    <collision>
      <origin
        xyz="0 0 0"
        rpy="0 0 0" />
      <geometry>
        <mesh
          filename="model://meshes/FL_wheel.STL" />
      </geometry>
	 <!--<mu1 value="100.0" />
	<mu2 value="100.0" />-->
    </collision>
  </link>
  <joint name="FRW_join"
    type="continuous">
    <origin
      xyz="0.180 0.110 -0.025"
      rpy="3.14 0 0" />
    <parent
      link="Susp_right" />
    <child
      link="FR_wheel" />
    <axis
      xyz="0 0 1" />
  <!--<limit effort="1000.0" lower="-1E15" upper="1E15" velocity="1E15"/>-->
  </joint>
  <link  name="BR_wheel">
    <inertial>
      <mass
        value="0.156306129053996" />
      <inertia
        ixx="0.01"
        ixy="0.000"
        ixz="0"
        iyy="0.01"
        iyz="0"
        izz="0.01" />
    </inertial>
    <visual>
      <origin
        xyz="0 0 0"
        rpy="0 0 0" />
      <geometry>
        <mesh
          filename="model://meshes/BR_wheel.STL" />
      </geometry>
      <material
        name="">
        <color
          rgba="0.298039215686275 0.298039215686275 0.298039215686275 1" />
      </material>
    </visual>
    <collision>
      <origin
        xyz="0 0 0"
        rpy="0 0 0" />
      <geometry>
        <mesh
          filename="model://meshes/BR_wheel.STL" />
      </geometry>
	 <!--<mu1 value="100.0" />
	<mu2 value="100.0" />-->
    </collision>
  </link>
  <joint name="BRW_join"
    type="continuous">
    <origin
      xyz="-0.180 0.110 -0.025"
      rpy="3.14 0 0" />
    <parent
      link="Susp_right" />
    <child
      link="BR_wheel" />
    <axis
      xyz="0 0 1" />
  </joint>
  <link  name="Susp_left">
    <inertial>
      <origin
        xyz="0 0 0"
        rpy="0 0 0" />
      <mass
        value="0.561111372554467" />
      <inertia
        ixx="0.01"
        ixy="0.000"
        ixz="0"
        iyy="0.01"
        iyz="0"
        izz="0.01" />
    </inertial>
    <visual>
      <origin
        xyz="0 0 0"
        rpy="0 0 0" />
      <geometry>
        <mesh
          filename="model://meshes/Susp_left.STL" />
      </geometry>
      <material
        name="">
        <color
          rgba="0.898039215686275 0.917647058823529 0.929411764705882 1" />
      </material>
    </visual>
    <collision>
      <origin
        xyz="0 0 0"
        rpy="0 0 0" />
      <geometry>
        <mesh
          filename="model://meshes/Susp_left.STL" />
      </geometry>
    </collision>
  </link>
  <joint name="Susp_left_join"
    type="fixed">
    <origin
      xyz="0 0.110 0"
      rpy="1.57 0 0" />
    <parent
      link="sagan_link" />
    <child
      link="Susp_left" />
    <axis
      xyz="0 1 0" />
  </joint>
  <link  name="FL_wheel">
    <inertial>
      <origin
        xyz="2.77555756156289E-17 0 0.0309919737738157"
        rpy="0 0 0" />
      <mass
        value="0.156306129053996" />
      <inertia
        ixx="0.01"
        ixy="0.000"
        ixz="0"
        iyy="0.01"
        iyz="0"
        izz="0.01" />
    </inertial>
    <visual>
      <origin
        xyz="0 0 0"
        rpy="0 0 0" />
      <geometry>
        <mesh
          filename="model://meshes/FL_wheel.STL" />
      </geometry>
      <material
        name="">
        <color
          rgba="0.898039215686275 0.917647058823529 0.929411764705882 1" />
      </material>
    </visual>
    <collision>
      <origin
        xyz="0 0 0"
        rpy="0 0 0" />
      <geometry>
        <mesh
          filename="model://meshes/FL_wheel.STL" />
      </geometry>
	 <!--<mu1 value="100.0" />
	<mu2 value="100.0" />-->
    </collision>
  </link>
  <joint name="FLW_join"
    type="continuous">
    <origin
      xyz="0.180 -0.110 -0.050"
      rpy="-3.14 0 0" />
    <parent
      link="Susp_left" />
    <child
      link="FL_wheel" />
    <axis
      xyz="0 0 1" />
  </joint>
  <link  name="BL_wheel">
    <inertial>
      <origin
        xyz="1.38777878078145E-17 2.77555756156289E-17 0.0309919737738156"
        rpy="0 0 0" />
      <mass
        value="0.156306129053996" />
      <inertia
        ixx="0.01"
        ixy="0"
        ixz="0"
        iyy="0.01"
        iyz="0"
        izz="0.01" />
    </inertial>
    <visual>
      <origin
        xyz="0 0 0"
        rpy="0 0 0" />
      <geometry>
        <mesh
          filename="model://meshes/BL_wheel.STL" />
      </geometry>
      <material
        name="">
        <color
          rgba="0.298039215686275 0.298039215686275 0.298039215686275 1" />
      </material>
    </visual>
    <collision>
      <origin
        xyz="0 0 0"
        rpy="0 0 0" />
      <geometry>
        <mesh
          filename="model://meshes/BL_wheel.STL" />
      </geometry>
	 <!--<mu1 value="100.0" />
	<mu2 value="100.0" />-->
    </collision>
  </link>
  <joint name="BLW_join"
    type="continuous">
    <origin
      xyz="-0.180 -0.110 -0.050"
      rpy="-3.14 0 0" />
    <parent
      link="Susp_left" />
    <child
      link="BL_wheel" />
    <!--<limit effort="1000.0" lower="0.0" upper="0.548" velocity="0.5"/>-->
    <axis
      xyz="0 0 1" />
  </joint>

  <gazebo>
    <plugin name="sagan_plugin" filename="libsagan_plugin.so">
    </plugin>
  </gazebo>

  <!-- definição ultrassonico -->
  <link name="hcsr04_link">
   <collision>
     <origin xyz="0 0 0" rpy="0 0 0"/>
     <geometry>
   <box size="0.02 0.05 0.02"/>
     </geometry>
   </collision>

   <visual>
     <origin xyz="0 0 0" rpy="0 0 0"/>
     <geometry>
   <box size="0.02 0.05 0.02"/>
     </geometry>
   </visual>

   <inertial>
     <mass value="1e-3" />
     <origin xyz="0 0 0" rpy="0 0 0"/>
     <inertia ixx="1e-3" ixy="0" ixz="0" iyy="1e-3" iyz="0" izz="1e-3" />
   </inertial>
 </link>

   <!-- Junta -->
   <joint name="hcsr04_joint" type="fixed">
   <axis xyz="0 1 0" />
   <origin xyz="0.175 0 0.05" rpy="0 0 0"/>
   <parent link="sagan_link"/>
   <child link="hcsr04_link"/>
 </joint>

  <!-- Plugin parametros ultrassonico -->
   <gazebo reference="hcsr04_link">
   <sensor type="ray" name="hcsr04_sensor">
     <pose>0 0 0 0 0 0</pose>
     <visualize>true</visualize>
     <update_rate>10</update_rate>
     <ray>
       <scan>
         <horizontal>
           <samples>10</samples>
           <resolution>1</resolution>
           <min_angle>-0.131</min_angle>
           <max_angle>0.131</max_angle>
         </horizontal>
   <vertical>
           <samples>10</samples>
           <resolution>1</resolution>
           <min_angle>-0.131</min_angle>
           <max_angle>0.131</max_angle>
         </vertical>
       </scan>
       <range>
         <min>0.05</min>
         <max>3.50</max>
         <resolution>1</resolution>
       </range>
       <noise>
         <type>gaussian</type>
         <!-- Noise parameters based on published spec for Hokuyo laser
              achieving "+-30mm" accuracy at range < 10m.  A mean of 0.0m and
              stddev of 0.01m will put 99.7% of samples within 0.03m of the true
              reading. -->
         <mean>0.0</mean>
         <stddev>0.01</stddev>
       </noise>
     </ray>
     <plugin name="gazebo_ros_hcsr04_controller" filename="libgazebo_ros_laser.so">
       <topicName>/sagan_gazebo/laser/scan</topicName>
       <frameName>hcsr04_link</frameName>
     </plugin>
   </sensor>
 </gazebo>




</robot>
